Workbook

Sheet Legend
A1: Alphabet Academy — Bid Workbook
A2: Forged Iron Works | Bid # AA25-188 (TEST RUN)
A5: How this workbook works
A6: Blue text | B6: Hardcoded input — edit these freely
A7: Black text | B7: Formula — do not overwrite, it recalculates automatically
A8: Yellow fill | B8: Needs a human decision (marked [CONFIRM WITH ARIE] or QUOTE REQUIRED) — bid is a DRAFT until these clear
A9: Green fill (Validation Gate tab) | B9: Check passed
A10: Red fill (Validation Gate tab) | B10: Check failed — do not submit this bid
A12: Sheet order / flow
A13: 1. Inputs | B13: Job-level inputs (tax, profit floor, etc.)
A14: 2. Rates | B14: Mirror of rates.md — do not hand-edit, update rates.md first, then re-sync
A15: 3. Takeoff | B15: Line-by-line material takeoff from drawings. Ext Wt and Pricing Group drive everything downstream.
A16: 4. Summary by Material | B16: Auto-check: totals by material type, ties out against Takeoff
A17: 5. Section 5 - Pricing | B17: Material/labor/equipment pricing, pulled from Takeoff by formula (not retyped)
A18: 6. Buyout & Hardware | B18: Flat-rate items (bolts, ladders, bollards, etc.)
A19: 7. Bid Summary | B19: Rolls everything up to Grand Total
A20: 8. Validation Gate | B20: MUST show all-clear before this bid leaves the building. See scope-rules.md Section 7.

Sheet Inputs
A1: Bid Inputs
A3: Project Name | B3: Alphabet Academy
A4: Client | B4: GPC Construction
A5: Bid # | B5: AA25-188 (TEST RUN)
A6: Scope Type | B6: Furnish & Erect (F&E)
A7: Tax Exempt (signed cert on file)? | B7: No
A8: Tax Rate (%) | B8: 0.07
A9: Profit Floor (%) [CONFIRM WITH ARIE] | B9: 0.117
A10: J&D Markup (%) | B10: 0.1
A11: Target Overall Margin (%) [CONFIRM WITH ARIE] | B11: 0.1
A12: Rounding Increment ($) | B12: 500
A13: Quote Valid (days) | B13: 14
A14: Erection Delay Charge ($) | B14: 1500

Sheet Rates
A1: Rate Reference
A2: Mirrors reference/rates.md — that file wins on conflict. Sync manually when rates.md changes.
A4: Category | B4: Item | C4: Unit | D4: Rate | E4: Notes
A6: Material Buy Rate | B6: WF Beams | C6: $/lb | D6: 1.2 | E6: ASTM A992 Gr. 50
A7: Material Buy Rate | B7: Tube / HSS | C7: $/lb | D7: 1.06 | E7: ASTM A500 Gr. B
A8: Material Buy Rate | B8: Angles | C8: $/lb | D8: 0.87 | E8: ASTM A36
A9: Material Buy Rate | B9: Channels | C9: $/lb | D9: 0.93 | E9: ASTM A36
A10: Material Buy Rate | B10: Flats | C10: $/lb | D10: 0.84 | E10: ASTM A36
A11: Material Buy Rate | B11: Bent Plate | C11: $/lb | D11: 1.35 | E11: ASTM A36
A12: Material Buy Rate | B12: Burned Plate | C12: $/lb | D12: 1.5 | E12: ASTM A36
A13: Material Buy Rate | B13: Misc Channels | C13: $/lb | D13: 1.12 | E13: ASTM A36
A14: Hardware | B14: Anchor Bolts | C14: $/EA | D14: 35
A15: Hardware | B15: Shear Studs | C15: $/EA | D15: 4.5 | E15: If composite deck
A16: Hardware | B16: Field Bolts | C16: $/EA | D16: 75 | E16: A325N
A17: Hardware | B17: Epoxy Anchors | C17: $/EA | D17: 75
A18: Hardware | B18: Bollards | C18: $/EA | D18: 195 | E18: Furnish only
A19: Service | B19: Painting | C19: $/hr | D19: 75 | E19: Applied to painted lbs
A20: Service | B20: Galvanizing | C20: $/lb | D20: 0.55 | E20: Applied to galvanized lbs
A21: Service | B21: Engineering | C21: $/ton | D21: 50 | E21: Only if required
A22: Service | B22: Detailing | C22: $/ton | D22: 250 | E22: Applied to total tonnage
A23: Service | B23: Shop Labor | C23: $/hr | D23: 75 | E23: Tons x 10 = shop hours
A24: Service | B24: Outbound Freight | C24: $/load | D24: 1200 | E24: Per truck
A25: Service | B25: J&D Markup | C25: % | D25: 0.1 | E25: Applied to joist & deck cost, before tax
A26: Erection Labor | B26: Local (< 50 mi) | C26: $/hr | D26: 75 | E26: Standard rate
A27: Erection Labor | B27: Regional (50-100 mi) | C27: $/hr | D27: 82
A28: Erection Labor | B28: Overnight (> 100 mi) | C28: $/hr | D28: 95 | E28: + per diem $65/man/day + hotel
A29: Equipment | B29: Crane | C29: $/hr | D29: 300 | E29: $80/hr if RAD crane
A30: Equipment | B30: Lull / Telehandler | C30: $/wk | D30: 1500
A31: Equipment | B31: Boom Lift | C31: $/wk | D31: 1225
A32: Equipment | B32: Scissor Lift | C32: $/wk | D32: 600
A33: Equipment | B33: Welder (machine) | C33: $/wk | D33: 200
A34: Misc Scope Item | B34: Dumpster / Trash Gates | C34: $/EA | D34: 5000
A35: Misc Scope Item | B35: Roof Access Ladder | C35: $/EA | D35: 2103 | E35: Buyout price - verify VLF
A36: Misc Scope Item | B36: Pipe Bollards | C36: $/EA | D36: 195 | E36: Furnish only
A37: Structural Package (ADDED 7/16) | B37: LH Joists | C37: $/joist | D37: QUOTE REQUIRED | E37: No standard rate - STOP per scope-rules.md S6
A38: Structural Package (ADDED 7/16) | B38: Metal Deck | C38: $/SF | D38: QUOTE REQUIRED | E38: No standard rate - STOP per scope-rules.md S6
A39: Production Benchmark | B39: Columns (set & detail) | C39: pcs/day | D39: 9
A40: Production Benchmark | B40: Beams | C40: pcs/day | D40: 9
A41: Production Benchmark | B41: Perimeter Angle | C41: LF/hr | D41: 38.4
A42: Production Benchmark | B42: Shop Labor multiplier | C42: hrs/ton | D42: 10
...

Sheet Takeoff
A1: Takeoff
A2: Every downstream sheet pulls from here by formula. Add rows here first, never in Section 5 directly.
A4: Item # | B4: Description | C4: Location/Area | D4: Material Type | E4: Pricing Group | F4: Qty | G4: Unit | H4: Unit Wt (lbs) | I4: Ext Wt (lbs) | J4: Waste % | K4: Ext Wt w/ Waste (lbs) | L4: Waste Flag | M4: Stock Length Used | N4: Notes
A6: 1 | B6: C2 Columns - HSS6x3x5/16 (Bull Moose Tube: 17.0 lb/ft) | C6: Canopy - Grid 9 | D6: Tube / HSS | E6: HSS Columns | F6: 3 | G6: EA | H6: 238 | I6: =IF(F6="","",F6*H6) -> 714 | J6: 0.08 | K6: =IF(I6="","",I6*(1+J6)) -> 771.12 | L6: =IF(J6="","",IF(J6>0.3,"HARD FAIL",IF(J6>=0.2,"CAUTION","PASS"))) -> PASS | M6: 14'-0" cut-to-length | N6: Confirmed spec per Arie 2026-07-16.
A7: 2 | B7: C3 Columns - HSS7x3x5/16 (Bull Moose Tube: 19.1 lb/ft) | C7: Canopy - Grid 4,6,7 | D7: Tube / HSS | E7: HSS Columns | F7: 6 | G7: EA | H7: 267.4 | I7: =IF(F7="","",F7*H7) -> 1604.4 | J7: 0.08 | K7: =IF(I7="","",I7*(1+J7)) -> 1732.752 | L7: =IF(J7="","",IF(J7>0.3,"HARD FAIL",IF(J7>=0.2,"CAUTION","PASS"))) -> PASS | M7: 14'-0" cut-to-length | N7: Confirmed spec per Arie 2026-07-16.
A8: 3 | B8: WF Beam W21x48 - Row 1 | C8: Canopy Row A, Bay 4-6 | D8: WF Beams | E8: WF Beams | F8: 1 | G8: EA | H8: 1200 | I8: =IF(F8="","",F8*H8) -> 1200 | J8: 0.08 | K8: =IF(I8="","",I8*(1+J8)) -> 1296 | L8: =IF(J8="","",IF(J8>0.3,"HARD FAIL",IF(J8>=0.2,"CAUTION","PASS"))) -> PASS | M8: 25'-0" (bay span) | N8: Grid-derived length, planning-stage assumption approved by Arie.
A9: 4 | B9: WF Beam W16x31 - Row 1 | C9: Canopy Row A, Bay 6-7 | D9: WF Beams | E9: WF Beams | F9: 1 | G9: EA | H9: 687.27 | I9: =IF(F9="","",F9*H9) -> 687.27 | J9: 0.08 | K9: =IF(I9="","",I9*(1+J9)) -> 742.2516 | L9: =IF(J9="","",IF(J9>0.3,"HARD FAIL",IF(J9>=0.2,"CAUTION","PASS"))) -> PASS | M9: 22'-2" (bay span) | N9: Grid-derived length.
A10: 5 | B10: WF Beam W21x48 - Row 1 | C10: Canopy Row A, Bay 7-8 | D10: WF Beams | E10: WF Beams | F10: 1 | G10: EA | H10: 932.16 | I10: =IF(F10="","",F10*H10) -> 932.16 | J10: 0.08 | K10: =IF(I10="","",I10*(1+J10)) -> 1006.7328 | L10: =IF(J10="","",IF(J10>0.3,"HARD FAIL",IF(J10>=0.2,"CAUTION","PASS"))) -> PASS | M10: 19'-5" (bay span) | N10: Grid-derived length.
A11: 6 | B11: WF Beam W21x44 - Row 1 | C11: Canopy Row A, Bay 8-9 | D11: WF Beams | E11: WF Beams | F11: 1 | G11: EA | H11: 979 | I11: =IF(F11="","",F11*H11) -> 979 | J11: 0.08 | K11: =IF(I11="","",I11*(1+J11)) -> 1057.32 | L11: =IF(J11="","",IF(J11>0.3,"HARD FAIL",IF(J11>=0.2,"CAUTION","PASS"))) -> PASS | M11: 22'-3" (bay span) | N11: Grid-derived length.
A12: 7 | B12: WF Beam W16x31 - Row 2 | C12: Canopy Row B, Bay 4-6 | D12: WF Beams | E12: WF Beams | F12: 1 | G12: EA | H12: 775 | I12: =IF(F12="","",F12*H12) -> 775 | J12: 0.08 | K12: =IF(I12="","",I12*(1+J12)) -> 837 | L12: =IF(J12="","",IF(J12>0.3,"HARD FAIL",IF(J12>=0.2,"CAUTION","PASS"))) -> PASS | M12: 25'-0" (bay span) | N12: Grid-derived length.
A13: 8 | B13: WF Beam W24x55 - Row 2 | C13: Canopy Row B, Bay 6-7 | D13: WF Beams | E13: WF Beams | F13: 1 | G13: EA | H13: 1219.35 | I13: =IF(F13="","",F13*H13) -> 1219.35 | J13: 0.08 | K13: =IF(I13="","",I13*(1+J13)) -> 1316.898 | L13: =IF(J13="","",IF(J13>0.3,"HARD FAIL",IF(J13>=0.2,"CAUTION","PASS"))) -> PASS | M13: 22'-2" (bay span) | N13: Grid-derived length.
A14: 9 | B14: WF Beam W21x44 - Row 2 | C14: Canopy Row B, Bay 7-8 | D14: WF Beams | E14: WF Beams | F14: 1 | G14: EA | H14: 854.48 | I14: =IF(F14="","",F14*H14) -> 854.48 | J14: 0.08 | K14: =IF(I14="","",I14*(1+J14)) -> 922.8384 | L14: =IF(J14="","",IF(J14>0.3,"HARD FAIL",IF(J14>=0.2,"CAUTION","PASS"))) -> PASS | M14: 19'-5" (bay span) | N14: Grid-derived length.
A15: 10 | B15: WF Beam W24x62 - Row 2 | C15: Canopy Row B, Bay 8-9 | D15: WF Beams | E15: WF Beams | F15: 1 | G15: EA | H15: 1379.5 | I15: =IF(F15="","",F15*H15) -> 1379.5 | J15: 0.08 | K15: =IF(I15="","",I15*(1+J15)) -> 1489.86 | L15: =IF(J15="","",IF(J15>0.3,"HARD FAIL",IF(J15>=0.2,"CAUTION","PASS"))) -> PASS | M15: 22'-3" (bay span) | N15: Grid-derived length.
A16: 11 | B16: WF Beam W12x16 - Row 2 (5th beam, no matching bay dim) | C16: Canopy Row B, Grid 9 area | D16: WF Beams | E16: WF Beams | F16: 1 | G16: EA | H16: 160 | I16: =IF(F16="","",F16*H16) -> 160 | J16: 0.08 | K16: =IF(I16="","",I16*(1+J16)) -> 172.8 | L16: =IF(J16="","",IF(J16>0.3,"HARD FAIL",IF(J16>=0.2,"CAUTION","PASS"))) -> PASS | M16: 10'-0" ASSUMED - not grid-derived | N16: NO matching bay dimension - weakest assumption, verify with EOR.
A17: 12 | B17: Perimeter Angle - assumed L3x3x1/4 (4.9 lb/ft) | C17: Building perimeter | D17: Angles | E17: Perimeter Angle | F17: 193 | G17: LF | H17: 4.9 | I17: =IF(F17="","",F17*H17) -> 945.7 | J17: 0.08 | K17: =IF(I17="","",I17*(1+J17)) -> 1021.356 | L17: =IF(J17="","",IF(J17>0.3,"HARD FAIL",IF(J17>=0.2,"CAUTION","PASS"))) -> PASS | M17: Per LF - stock length TBD | N17: SIZE UNCONFIRMED. A-105 shows CMU parapet - may mean no edge angle needed - flag to estimator.
... A20: 15 | B20: Loose Lintels - Corridor 133 door (3'-6"), L4x3-1/2x1/4 6.2 lb/ft | C20: Classroom wing exterior | D20: Angles | E20: Loose Lintels | F20: 1 | G20: OPENING | H20: 64.108 | I20: =IF(F20="","",F20*H20) -> 64.108 | J20: 0.08 | K20: =IF(I20="","",I20*(1+J20)) -> 69.23664 | L20: =IF(J20="","",IF(J20>0.3,"HARD FAIL",IF(J20>=0.2,"CAUTION","PASS"))) -> PASS | M20: ~5'-2" per angle | N20: Furnish only. Borderline size, conservative tier.

Sheet Summary by Material
A1: Summary by Material
A2: Reconciliation check — ties Takeoff totals to Section 5 Pricing totals (scope-rules.md S6).
A4: Material Type | B4: Total Qty | C4: Total Weight, incl waste (lbs)
A6: WF Beams | B6: =SUMIF(Takeoff!$D$6:$D$20,A6,Takeoff!$F$6:$F$20) -> 9 | C6: =SUMIF(Takeoff!$D$6:$D$20,A6,Takeoff!$K$6:$K$20) -> 8841.7008
A7: Tube / HSS | B7: =SUMIF(Takeoff!$D$6:$D$20,A7,Takeoff!$F$6:$F$20) -> 9 | C7: =SUMIF(Takeoff!$D$6:$D$20,A7,Takeoff!$K$6:$K$20) -> 2503.872
A8: Angles | B8: =SUMIF(Takeoff!$D$6:$D$20,A8,Takeoff!$F$6:$F$20) -> 206 | C8: =SUMIF(Takeoff!$D$6:$D$20,A8,Takeoff!$K$6:$K$20) -> 1963.9195
A9: Channels | B9: =SUMIF(Takeoff!$D$6:$D$20,A9,Takeoff!$F$6:$F$20) -> 0 | C9: =SUMIF(Takeoff!$D$6:$D$20,A9,Takeoff!$K$6:$K$20) -> 0
A10: Flats | B10: =SUMIF(Takeoff!$D$6:$D$20,A10,Takeoff!$F$6:$F$20) -> 0 | C10: =SUMIF(Takeoff!$D$6:$D$20,A10,Takeoff!$K$6:$K$20) -> 0
A11: Bent Plate | B11: =SUMIF(Takeoff!$D$6:$D$20,A11,Takeoff!$F$6:$F$20) -> 0 | C11: =SUMIF(Takeoff!$D$6:$D$20,A11,Takeoff!$K$6:$K$20) -> 0
A12: Burned Plate | B12: =SUMIF(Takeoff!$D$6:$D$20,A12,Takeoff!$F$6:$F$20) -> 0 | C12: =SUMIF(Takeoff!$D$6:$D$20,A12,Takeoff!$K$6:$K$20) -> 0
A13: Misc Channels | B13: =SUMIF(Takeoff!$D$6:$D$20,A13,Takeoff!$F$6:$F$20) -> 0 | C13: =SUMIF(Takeoff!$D$6:$D$20,A13,Takeoff!$K$6:$K$20) -> 0
A14: TOTAL (all material, incl waste) | C14: =SUM(C6:C13) -> 13309.492
A15: TOTAL TONS (incl waste) | C15: =C14/2000 -> 6.6547462

Sheet Section 5 - Pricing
A1: Section 5 - Pricing
A2: Material Qty pulls from Takeoff by Pricing Group. Labor Hrs pulls from Rates production benchmarks. Nothing here is retyped by hand.
A4: Item # | B4: Description | C4: Material Type | D4: Material Qty (lbs) | E4: Material Rate ($/lb) | F4: Labor Hrs | G4: Labor Rate ($/hr) | H4: Equip Hrs/Units | I4: Equip Rate | J4: Ext Material | K4: Ext Labor | L4: Ext Equip | M4: Line Total | N4: Status
A6: 1 | B6: HSS Columns (C2 + C3, canopy) | C6: Tube / HSS | D6: =SUMIF(Takeoff!$E$6:$E$20,"HSS Columns",Takeoff!$K$6:$K$20) -> 2503.872 | E6: =IFERROR(VLOOKUP(C6,Rates!$B$6:$D$43,3,FALSE()),"") -> 1.06 | F6: =ROUNDUP(SUMIF(Takeoff!$E$6:$E$20,"HSS Columns",Takeoff!$F$6:$F$20)/VLOOKUP("Columns (set & detail)",Rates!$B$6:$D$43,3,FALSE()),0)*8 -> 8 | G6: =IFERROR(VLOOKUP("Local (< 50 mi)",Rates!$B$6:$D$43,3,FALSE()),75) -> 75 | H6: 0 | I6: 0 | J6: =IF(D6="","",IF(Inputs!$B$6="Erect Only",0,D6*E6)) -> 2654.1043 | K6: =IF(F6="","",F6*G6) -> 600 | L6: =IF(H6="","",H6*I6) -> 0 | M6: =SUM(J6:L6) -> 3254.1043 | N6: PRICED
A7: 2 | B7: 9x WF Beams, canopy frame (bay-spacing assumption, see Takeoff notes) | C7: WF Beams | D7: =SUMIF(Takeoff!$E$6:$E$20,"WF Beams",Takeoff!$K$6:$K$20) -> 8841.7008 | E7: =IFERROR(VLOOKUP(C7,Rates!$B$6:$D$43,3,FALSE()),"") -> 1.2 | F7: =ROUNDUP(SUMIF(Takeoff!$E$6:$E$20,"WF Beams",Takeoff!$F$6:$F$20)/VLOOKUP("Beams",Rates!$B$6:$D$43,3,FALSE()),0)*8 -> 8 | G7: =IFERROR(VLOOKUP("Local (< 50 mi)",Rates!$B$6:$D$43,3,FALSE()),75) -> 75 | H7: 0 | I7: 0 | J7: =IF(D7="","",IF(Inputs!$B$6="Erect Only",0,D7*E7)) -> 10610.041 | K7: =IF(F7="","",F7*G7) -> 600 | L7: =IF(H7="","",H7*I7) -> 0 | M7: =SUM(J7:L7) -> 11210.041 | N7: PRICED
A8: 3 | B8: Perimeter Angle - 193 LF assumed L3x3x1/4 (size UNCONFIRMED on drawings) | C8: Angles | D8: =SUMIF(Takeoff!$E$6:$E$20,"Perimeter Angle",Takeoff!$K$6:$K$20) -> 1021.356 | E8: =IFERROR(VLOOKUP(C8,Rates!$B$6:$D$43,3,FALSE()),"") -> 0.87 | F8: =SUMIF(Takeoff!$E$6:$E$20,"Perimeter Angle",Takeoff!$F$6:$F$20)/VLOOKUP("Perimeter Angle",Rates!$B$6:$D$43,3,FALSE()) -> 5.0260417 | G8: =IFERROR(VLOOKUP("Local (< 50 mi)",Rates!$B$6:$D$43,3,FALSE()),75) -> 75 | H8: 0 | I8: 0 | J8: =IF(D8="","",IF(Inputs!$B$6="Erect Only",0,D8*E8)) -> 888.57972 | K8: =IF(F8="","",F8*G8) -> 376.95312 | L8: =IF(H8="","",H8*I8) -> 0 | M8: =SUM(J8:L8) -> 1265.5328 | N8: FLAGGED - size unconfirmed, verify vs. A-105 parapet detail before submitting
A9: 4 | B9: Loose Lintels - 13 openings, furnish only (zero labor per scope-rules.md S5), galvanized | C9: Angles | D9: =SUMIF(Takeoff!$E$6:$E$20,"Loose Lintels",Takeoff!$K$6:$K$20) -> 942.56352 | E9: =IFERROR(VLOOKUP(C9,Rates!$B$6:$D$43,3,FALSE()),"") -> 0.87 | F9: 0 | G9: 0 | H9: =D9 -> 942.56352 | I9: =IFERROR(VLOOKUP("Galvanizing",Rates!$B$6:$D$43,3,FALSE()),"") -> 0.55 | J9: =IF(D9="","",IF(Inputs!$B$6="Erect Only",0,D9*E9)) -> 820.03026 | K9: =IF(F9="","",F9*G9) -> 0 | L9: 0 | M9: =SUM(J9:L9) -> 820.03026 | N9: FLAGGED - exterior window schedule not yet cross-referenced, opening count may be incomplete
A10: 5 | B10: Shop Labor (total tonnage x 10 hrs/ton) | F10: ='Summary by Material'!C15*VLOOKUP("Shop Labor multiplier",Rates!$B$6:$D$43,3,FALSE()) -> 66.547462 | G10: =IFERROR(VLOOKUP("Shop Labor",Rates!$B$6:$D$43,3,FALSE()),"") -> 75 | H10: 0 | I10: 0 | J10: =IF(D10="","",IF(Inputs!$B$6="Erect Only",0,D10*E10)) | K10: =IF(F10="","",F10*G10) -> 4991.0596 | L10: =IF(H10="","",H10*I10) -> 0 | M10: =SUM(J10:L10) -> 4991.0596 | N10: PRICED
A11: 6 | B11: LH Joists (11 EA, 48LH10) - NOT IN TAKEOFF, no rate exists | C11: N/A | D11: QUOTE REQUIRED | E11: QUOTE REQUIRED | F11: QUOTE REQUIRED | G11: QUOTE REQUIRED | H11: QUOTE REQUIRED | I11: QUOTE REQUIRED | J11: 0 | K11: 0 | L11: 0 | M11: =SUM(J11:L11) -> 0 | N11: FLAGGED - STOP per scope-rules.md S6, needs supplier quote before pricing
A12: 7 | B12: Metal Deck (45 sq / 4,500 SF) - NOT IN TAKEOFF, no rate exists | C12: N/A | D12: QUOTE REQUIRED | E12: QUOTE REQUIRED | F12: QUOTE REQUIRED | G12: QUOTE REQUIRED | H12: QUOTE REQUIRED | I12: QUOTE REQUIRED | J12: 0 | K12: 0 | L12: 0 | M12: =SUM(J12:L12) -> 0 | N12: FLAGGED - STOP per scope-rules.md S6, needs supplier quote before pricing
A13: 8 | B13: Field Bolts - beam-to-column moment connections (9 columns x 9 beams) | C13: Hardware | D13: N/A | E13: N/A | F13: 0 | G13: 0 | H13: CONFIRM WITH ARIE | I13: =IFERROR(VLOOKUP("Field Bolts",Rates!$B$6:$D$43,3,FALSE()),"") -> 75 | J13: 0 | K13: =IF(F13="","",F13*G13) -> 0 | L13: 0 | M13: =SUM(J13:L13) -> 0 | N13: FLAGGED - no bolts-per-connection standard yet, see scope-rules.md S5B
A14: 9 | B14: Painting - canopy steel to match building canopy (CHARCOAL), per site detail | C14: Service | F14: CONFIRM WITH ARIE | G14: =IFERROR(VLOOKUP("Painting",Rates!$B$6:$D$43,3,FALSE()),"") -> 75 | H14: 0 | I14: 0 | J14: =IF(D14="","",IF(Inputs!$B$6="Erect Only",0,D14*E14)) | K14: 0 | L14: =IF(H14="","",H14*I14) -> 0 | M14: =SUM(J14:L14) -> 0 | N14: FLAGGED - no lbs/hr production rate exists yet, see rates.md
A16: TOTALS | J16: =SUM(J6:J14) -> 14972.755 | K16: =SUM(K6:K14) -> 6568.0127 | L16: =SUM(L6:L14) -> 0

Sheet Buyout & Hardware
A1: Buyout & Hardware
A3: Item | B3: Qty | C3: Unit | D3: Rate (auto) | E3: Ext Cost
A6: Anchor Bolts | B6: 36 | C6: EA | D6: =IFERROR(VLOOKUP(A6,Rates!$B$6:$D$43,3,FALSE()),"") -> 35 | E6: =IF(A6="","",IF(Inputs!$B$6="Erect Only",0,B6*D6)) -> 1260
A7: Bollards | B7: 2 | C7: EA | D7: =IFERROR(VLOOKUP(A7,Rates!$B$6:$D$43,3,FALSE()),"") -> 195 | E7: =IF(A7="","",IF(Inputs!$B$6="Erect Only",0,B7*D7)) -> 390
A8: Roof Access Ladder | B8: 1 | C8: EA | D8: =IFERROR(VLOOKUP(A8,Rates!$B$6:$D$43,3,FALSE()),"") -> 2103 | E8: =IF(A8="","",IF(Inputs!$B$6="Erect Only",0,B8*D8)) -> 2103
D9: =IFERROR(VLOOKUP(A9,Rates!$B$6:$D$43,3,FALSE()),"") | E9: =IF(A9="","",IF(Inputs!$B$6="Erect Only",0,B9*D9))
D10: =IFERROR(VLOOKUP(A10,Rates!$B$6:$D$43,3,FALSE()),"") | E10: =IF(A10="","",IF(Inputs!$B$6="Erect Only",0,B10*D10))
D11: =IFERROR(VLOOKUP(A11,Rates!$B$6:$D$43,3,FALSE()),"") | E11: =IF(A11="","",IF(Inputs!$B$6="Erect Only",0,B11*D11))
D12: =IFERROR(VLOOKUP(A12,Rates!$B$6:$D$43,3,FALSE()),"") | E12: =IF(A12="","",IF(Inputs!$B$6="Erect Only",0,B12*D12))
D13: =IFERROR(VLOOKUP(A13,Rates!$B$6:$D$43,3,FALSE()),"") | E13: =IF(A13="","",IF(Inputs!$B$6="Erect Only",0,B13*D13))
D14: =IFERROR(VLOOKUP(A14,Rates!$B$6:$D$43,3,FALSE()),"") | E14: =IF(A14="","",IF(Inputs!$B$6="Erect Only",0,B14*D14))
A15: TOTAL | E15: =SUM(E6:E14) -> 3753

Sheet Bid Summary
A1: Bid Summary
A4: Tonnage Material Subtotal | B4: ='Section 5 - Pricing'!J16 -> 14972.755
A5: Buyout & Hardware Subtotal | B5: ='Buyout & Hardware'!E15 -> 3753
A6: Joist & Deck Cost (input - awaiting supplier quote) | B6: 0
A7: Joist & Deck After Markup | B7: =IF(Inputs!$B$6="Erect Only",0,B6*(1+Inputs!$B$10)) -> 0
A8: Taxable Base (material + hardware + J&D) | B8: =B4+B5+B7 -> 18725.755
A9: Erection Labor Subtotal | B9: ='Section 5 - Pricing'!K16 -> 6568.0127
A10: Equipment Subtotal | B10: ='Section 5 - Pricing'!L16 -> 0
A11: Freight (input) | B11: 1200
A12: Engineering (input) | B12: 0
A13: Detailing (auto = total tons x $250/ton) | B13: ='Summary by Material'!C15*VLOOKUP("Detailing",Rates!$B$6:$D$43,3,FALSE()) -> 1663.6865
A14: Non-Taxable Subtotal | B14: =SUM(B9:B13) -> 9431.6993
A15: Direct Cost Subtotal (Sub Total) | B15: =B8+B14 -> 28157.455
A16: Bond Required? (Yes/No) | B16: No
A17: Bond Rate (%) - leave blank if using flat $
A18: Bond Amount ($, flat) - leave blank if using Rate %
A19: Bond Total ($) | B19: =IF(B16<>"Yes",0,IF(B17="",IF(B18="",0,B18),B15*B17)) -> 0
A20: Profit (Profit Floor % x Sub Total, excl. Bond) | B20: =B15*Inputs!$B$9 -> 3294.4222
A21: Tax (Tax Rate x Taxable Base, excl. Bond) | B21: =IF(Inputs!$B$7="Yes",0,B8*Inputs!$B$8) -> 1310.8029
A22: Pre-Rounding Total | B22: =B15+B19+B20+B21 -> 32762.68
A23: Grand Total (rounded up) | B23: =CEILING(B22,Inputs!$B$12) -> 33000
A24: Margin Sanity Check (Profit / Grand Total) | B24: =B20/B23 -> 0.099830975
A25: Sanity Check Result | B25: =IF(B24>=Inputs!$B$11,"PASS","BELOW TARGET - raise Profit Floor %, do not touch material rates") -> BELOW TARGET - raise Profit Floor %, do not touch material rates

Sheet Validation Gate
A1: Validation Gate
A2: scope-rules.md Section 7 - Mandatory Pre-Submission Gate. This bid may not go out while any row below reads FAIL.
A4: Check | B4: Result | C4: Detail
A6: No FLAGGED rows remain in Section 5 - Pricing | B6: =IF(COUNTIF('Section 5 - Pricing'!N6:N14,"FLAGGED*")=0,"PASS","FAIL") -> FAIL | C6: =COUNTIF('Section 5 - Pricing'!N6:N14,"FLAGGED*")&" flagged row(s) - see Status column" -> 6 flagged row(s) - see Status column
A7: No waste % HARD FAIL in Takeoff | B7: =IF(COUNTIF(Takeoff!L6:L20,"HARD FAIL")=0,"PASS","FAIL") -> PASS | C7: =COUNTIF(Takeoff!L6:L20,"HARD FAIL")&" line(s) exceed 30% waste" -> 0 line(s) exceed 30% waste
A8: Tonnage reconciles: Takeoff total = Section 5 material basis | B8: =IF(ROUND('Summary by Material'!C15*2000,0)=ROUND(SUM(Takeoff!K6:K20),0),"PASS","FAIL") -> PASS | C8: Total weight incl. waste must match between Summary by Material and raw Takeoff sum
A9: Margin Sanity Check meets target | B9: ='Bid Summary'!B24 -> 0.099830975
A10: Joist & Deck priced from real quote (not $0 placeholder) | B10: =IF('Bid Summary'!B6>0,"PASS","FAIL - awaiting supplier quote") -> FAIL - awaiting supplier quote
A11: Field Bolts quantified (not blank/placeholder) | B11: =IF(ISNUMBER('Section 5 - Pricing'!H13),"PASS","FAIL - awaiting bolts-per-connection standard from Arie") -> FAIL - awaiting bolts-per-connection standard from Arie
A12: Painting priced (not blank/placeholder) | B12: =IF(ISNUMBER('Section 5 - Pricing'!F14),"PASS","FAIL - awaiting production rate from Arie") -> FAIL - awaiting production rate from Arie
A13: Perimeter Angle size confirmed | B13: ="MANUAL CHECK - see Takeoff row for Perimeter Angle, flagged pending A-105 review" -> MANUAL CHECK - see Takeoff row for Perimeter Angle, flagged pending A-105 review
A14: Loose Lintel openings cross-checked vs. window schedule | B14: ="MANUAL CHECK - currently door-schedule-only, see Takeoff notes" -> MANUAL CHECK - currently door-schedule-only, see Takeoff notes
A16: OVERALL STATUS | B16: =IF(COUNTIF(B6:B14,"FAIL*")>0,"DRAFT - DO NOT SUBMIT","READY FOR REVIEW") -> DRAFT - DO NOT SUBMIT
