Workbook

Sheet Inputs
A1: Bid Inputs
A3: Project Name | B3: Alphabet Academy
A4: Client | B4: GPC Construction
A5: Bid # | B5: AA25-188 (TEST RUN)
A6: Scope Type | B6: Furnish & Erect (F&E)
A7: Tax Exempt (signed cert on file)? | B7: No
A8: Tax Rate (%) | B8: 0.07
A9: Profit Floor (%) [CONFIRM WITH ARIE - see scope-rules.md #4] | B9: 0.117
A10: J&D Markup (%) | B10: 0.1
A11: Target Overall Margin (%) [CONFIRM WITH ARIE] | B11: 0.1
A12: Rounding Increment ($ - SOP allows 500 or 1,000) | B12: 500
A13: Quote Valid (days) | B13: 14
A14: Erection Delay Charge ($) | B14: 1500

Sheet Rates
A1: Rates (mirror of reference/rates.md — keep in sync, that file wins on conflict)
A3: Category | B3: Item | C3: Unit | D3: Rate | E3: Notes
A4: Material Buy Rate | B4: WF Beams | C4: $/lb | D4: 1.2 | E4: ASTM A992 Gr. 50 (Cost Code 50004)
A5: Material Buy Rate | B5: Tube / HSS | C5: $/lb | D5: 1.06 | E5: ASTM A500 Gr. B (Cost Code 50004)
A6: Material Buy Rate | B6: Angles | C6: $/lb | D6: 0.87 | E6: ASTM A36 (Cost Code 50004)
A7: Material Buy Rate | B7: Channels | C7: $/lb | D7: 0.93 | E7: ASTM A36 (Cost Code 50004)
A8: Material Buy Rate | B8: Flats | C8: $/lb | D8: 0.84 | E8: ASTM A36 (Cost Code 50004)
A9: Material Buy Rate | B9: Bent Plate | C9: $/lb | D9: 1.35 | E9: ASTM A36 (Cost Code 50004)
A10: Material Buy Rate | B10: Burned Plate | C10: $/lb | D10: 1.5 | E10: ASTM A36 (Cost Code 50004)
A11: Material Buy Rate | B11: Misc Channels | C11: $/lb | D11: 1.12 | E11: ASTM A36 (Cost Code 50004)
A12: Hardware | B12: Anchor Bolts | C12: $/EA | D12: 35 | E12: Cost Code 50004
A13: Hardware | B13: Shear Studs | C13: $/EA | D13: 4.5 | E13: If composite deck (Cost Code 50004)
A14: Hardware | B14: Field Bolts | C14: $/EA | D14: 75 | E14: A325N (Cost Code 50005)
A15: Hardware | B15: Epoxy Anchors | C15: $/EA | D15: 75 | E15: Cost Code 50004
... A25: Erection Labor | B25: Local (< 50 miles) | C25: $/hr | D25: 75 | E25: Standard rate
A26: Erection Labor | B26: Regional (50-100 miles) | C26: $/hr | D26: 82
A27: Erection Labor | B27: Overnight / Travel (> 100 mi) | C27: $/hr | D27: 95 | E27: + per diem $65/man/day + hotel ~$175/night (2 men/room)
A28: Equipment | B28: Crane | C28: $/hr | D28: 300 | E28: $80/hr if RAD crane
A29: Equipment | B29: Lull / Telehandler | C29: $/wk | D29: 1500
A30: Equipment | B30: Boom Lift | C30: $/wk | D30: 1225
A31: Equipment | B31: Scissor Lift | C31: $/wk | D31: 600
A32: Equipment | B32: Welder (machine) | C32: $/wk | D32: 200
A33: Equipment | B33: Scaffold | C33: $/day/floor | D33: 1000
A34: Equipment | B34: Perimeter Cable | C34: $/day/ft | D34: 25
A35: Equipment | B35: Equipment Delivery | C35: $/EA | D35: 1000
A36: Equipment | B36: Material Delivery | C36: $/load | D36: 1200
A37: Misc Scope Item | B37: Dumpster / Trash Gates | C37: $/EA | D37: 5000
A38: Misc Scope Item | B38: Roof Access Ladder | C38: $/EA | D38: 2103 | E38: Buyout price - verify VLF
A39: Misc Scope Item | B39: Steel Railing - 2-Line | C39: $/LF | D39: 200
A40: Misc Scope Item | B40: Repair Rail | C40: $/LF | D40: 200
A41: Misc Scope Item | B41: Cable Railing | C41: $/LF | D41: 650
A42: Misc Scope Item | B42: Wall Fix (railing) | C42: $/EA | D42: 800
A43: Misc Scope Item | B43: Pipe Bollards | C43: $/EA | D43: 195 | E43: Furnish only
A44: Misc Scope Item | B44: Grating | C44: N/A | E44: No standard rate - price by SF or LF per job
A45: Misc Scope Item | B45: Fall Protection Anchors | C45: N/A | E45: Quote per install
A46: Production Benchmark | B46: Columns (set & detail) | C46: pcs/day | D46: 9 | E46: Adjust for height & connections
A47: Production Benchmark | B47: Beams | C47: pcs/day | D47: 9 | E47: Adjust for moment connections
A48: Production Benchmark | B48: Joists (K-series) | C48: pcs/day | D48: 192
A49: Production Benchmark | B49: Perimeter Angle | C49: LF/hr | D49: 38.4 | E49: Continuous runs
A50: Production Benchmark | B50: Metal Deck | C50: sq/day | D50: 45 | E50: Per square (100 SF)
...

Sheet Section 5 - Pricing
A1: Item # | B1: Description | C1: Material Type | D1: Material Qty (lbs) | E1: Material Rate ($/lb, auto) | F1: Labor Hrs | G1: Labor Rate ($/hr) | H1: Equip Hrs/Units | I1: Equip Rate | J1: Ext Material | K1: Ext Labor | L1: Ext Equip | M1: Line Total
A2: 1 | B2: HSS Columns (3x C2 HSS6x3x5/16 @ 17.0 lb/ft + 6x C3 HSS7x3x5/16 @ 19.1 lb/ft, 14'-0" tall) | C2: Tube / HSS | D2: 2503.872 | E2: =IFERROR(VLOOKUP(C2,Rates!$B$4:$D$100,3,FALSE),"") | F2: 8 | G2: 75 | H2: 0 | I2: 0 | J2: =IF(D2="","",IF(Inputs!$B$6="Erect Only",0,D2*E2)) | K2: =IF(F2="","",F2*G2) | L2: =IF(H2="","",H2*I2) | M2: =SUM(J2:L2)
A3: 2 | B3: 9x WF Beams, canopy frame (bay-spacing assumption, see takeoff notes) | C3: WF Beams | D3: 8841.7008 | E3: =IFERROR(VLOOKUP(C3,Rates!$B$4:$D$100,3,FALSE),"") | F3: 8 | G3: 75 | H3: 0 | I3: 0 | J3: =IF(D3="","",IF(Inputs!$B$6="Erect Only",0,D3*E3)) | K3: =IF(F3="","",F3*G3) | L3: =IF(H3="","",H3*I3) | M3: =SUM(J3:L3)
A4: 3 | B4: Perimeter Angle - 193 LF assumed L3x3x1/4 (size unconfirmed on drawings) | C4: Angles | D4: 1021.356 | E4: =IFERROR(VLOOKUP(C4,Rates!$B$4:$D$100,3,FALSE),"") | F4: 5.0260417 | G4: 75 | H4: 0 | I4: 0 | J4: =IF(D4="","",IF(Inputs!$B$6="Erect Only",0,D4*E4)) | K4: =IF(F4="","",F4*G4) | L4: =IF(H4="","",H4*I4) | M4: =SUM(J4:L4)
A5: 4 | B5: Loose Lintels - 13 openings, furnish only (zero labor), galvanized | C5: Angles | D5: 942.56352 | E5: =IFERROR(VLOOKUP(C5,Rates!$B$4:$D$100,3,FALSE),"") | F5: 0 | G5: 0 | H5: 942.56352 | I5: 0.55 | J5: =IF(D5="","",IF(Inputs!$B$6="Erect Only",0,D5*E5)) | K5: =IF(F5="","",F5*G5) | L5: =IF(H5="","",H5*I5) | M5: =SUM(J5:L5)
A6: 5 | B6: Shop Labor (6.655 tons x 10 hrs/ton) | E6: =IFERROR(VLOOKUP(C6,Rates!$B$4:$D$100,3,FALSE),"") | F6: 66.547462 | G6: 75 | H6: 0 | I6: 0 | J6: =IF(D6="","",IF(Inputs!$B$6="Erect Only",0,D6*E6)) | K6: =IF(F6="","",F6*G6) | L6: =IF(H6="","",H6*I6) | M6: =SUM(J6:L6)
E7: =IFERROR(VLOOKUP(C7,Rates!$B$4:$D$100,3,FALSE),"") | J7: =IF(D7="","",IF(Inputs!$B$6="Erect Only",0,D7*E7)) | K7: =IF(F7="","",F7*G7) | L7: =IF(H7="","",H7*I7) | M7: =SUM(J7:L7)
E8: =IFERROR(VLOOKUP(C8,Rates!$B$4:$D$100,3,FALSE),"") | J8: =IF(D8="","",IF(Inputs!$B$6="Erect Only",0,D8*E8)) | K8: =IF(F8="","",F8*G8) | L8: =IF(H8="","",H8*I8) | M8: =SUM(J8:L8)
E9: =IFERROR(VLOOKUP(C9,Rates!$B$4:$D$100,3,FALSE),"") | J9: =IF(D9="","",IF(Inputs!$B$6="Erect Only",0,D9*E9)) | K9: =IF(F9="","",F9*G9) | L9: =IF(H9="","",H9*I9) | M9: =SUM(J9:L9)
E10: =IFERROR(VLOOKUP(C10,Rates!$B$4:$D$100,3,FALSE),"") | J10: =IF(D10="","",IF(Inputs!$B$6="Erect Only",0,D10*E10)) | K10: =IF(F10="","",F10*G10) | L10: =IF(H10="","",H10*I10) | M10: =SUM(J10:L10)
E11: =IFERROR(VLOOKUP(C11,Rates!$B$4:$D$100,3,FALSE),"") | J11: =IF(D11="","",IF(Inputs!$B$6="Erect Only",0,D11*E11)) | K11: =IF(F11="","",F11*G11) | L11: =IF(H11="","",H11*I11) | M11: =SUM(J11:L11)
E12: =IFERROR(VLOOKUP(C12,Rates!$B$4:$D$100,3,FALSE),"") | J12: =IF(D12="","",IF(Inputs!$B$6="Erect Only",0,D12*E12)) | K12: =IF(F12="","",F12*G12) | L12: =IF(H12="","",H12*I12) | M12: =SUM(J12:L12)
E13: =IFERROR(VLOOKUP(C13,Rates!$B$4:$D$100,3,FALSE),"") | J13: =IF(D13="","",IF(Inputs!$B$6="Erect Only",0,D13*E13)) | K13: =IF(F13="","",F13*G13) | L13: =IF(H13="","",H13*I13) | M13: =SUM(J13:L13)
E14: =IFERROR(VLOOKUP(C14,Rates!$B$4:$D$100,3,FALSE),"") | J14: =IF(D14="","",IF(Inputs!$B$6="Erect Only",0,D14*E14)) | K14: =IF(F14="","",F14*G14) | L14: =IF(H14="","",H14*I14) | M14: =SUM(J14:L14)
E15: =IFERROR(VLOOKUP(C15,Rates!$B$4:$D$100,3,FALSE),"") | J15: =IF(D15="","",IF(Inputs!$B$6="Erect Only",0,D15*E15)) | K15: =IF(F15="","",F15*G15) | L15: =IF(H15="","",H15*I15) | M15: =SUM(J15:L15)
E16: =IFERROR(VLOOKUP(C16,Rates!$B$4:$D$100,3,FALSE),"") | J16: =IF(D16="","",IF(Inputs!$B$6="Erect Only",0,D16*E16)) | K16: =IF(F16="","",F16*G16) | L16: =IF(H16="","",H16*I16) | M16: =SUM(J16:L16)
E17: =IFERROR(VLOOKUP(C17,Rates!$B$4:$D$100,3,FALSE),"") | J17: =IF(D17="","",IF(Inputs!$B$6="Erect Only",0,D17*E17)) | K17: =IF(F17="","",F17*G17) | L17: =IF(H17="","",H17*I17) | M17: =SUM(J17:L17)
E18: =IFERROR(VLOOKUP(C18,Rates!$B$4:$D$100,3,FALSE),"") | J18: =IF(D18="","",IF(Inputs!$B$6="Erect Only",0,D18*E18)) | K18: =IF(F18="","",F18*G18) | L18: =IF(H18="","",H18*I18) | M18: =SUM(J18:L18)
... E31: =IFERROR(VLOOKUP(C31,Rates!$B$4:$D$100,3,FALSE),"") | J31: =IF(D31="","",IF(Inputs!$B$6="Erect Only",0,D31*E31)) | K31: =IF(F31="","",F31*G31) | L31: =IF(H31="","",H31*I31) | M31: =SUM(J31:L31)
A32: TOTALS | J32: =SUM(J2:J31) | K32: =SUM(K2:K31) | L32: =SUM(L2:L31) | M32: =SUM(M2:M31)
A34: Ext Material forces to $0 when Inputs!Scope Type = "Erect Only", per scope-rules.md Section 1: skip ALL material cost rows entirely for erect-only jobs. Material/Labor/Equipment each use their own quantity column so lbs, hrs, and equipment-hrs never cross-multiply.

Sheet Buyout & Hardware
A1: Item | B1: Qty | C1: Unit | D1: Rate (auto) | E1: Ext Cost
A2: Anchor Bolts | B2: 36 | C2: EA | D2: =IFERROR(VLOOKUP(A2,Rates!$B$4:$D$100,3,FALSE),"") | E2: =IF(A2="","",IF(Inputs!$B$6="Erect Only",0,B2*D2))
A3: Bollards | B3: 2 | C3: EA | D3: =IFERROR(VLOOKUP(A3,Rates!$B$4:$D$100,3,FALSE),"") | E3: =IF(A3="","",IF(Inputs!$B$6="Erect Only",0,B3*D3))
A4: Roof Access Ladder | B4: 1 | C4: EA | D4: =IFERROR(VLOOKUP(A4,Rates!$B$4:$D$100,3,FALSE),"") | E4: =IF(A4="","",IF(Inputs!$B$6="Erect Only",0,B4*D4))
D5: =IFERROR(VLOOKUP(A5,Rates!$B$4:$D$100,3,FALSE),"") | E5: =IF(A5="","",IF(Inputs!$B$6="Erect Only",0,B5*D5))
D6: =IFERROR(VLOOKUP(A6,Rates!$B$4:$D$100,3,FALSE),"") | E6: =IF(A6="","",IF(Inputs!$B$6="Erect Only",0,B6*D6))
D7: =IFERROR(VLOOKUP(A7,Rates!$B$4:$D$100,3,FALSE),"") | E7: =IF(A7="","",IF(Inputs!$B$6="Erect Only",0,B7*D7))
D8: =IFERROR(VLOOKUP(A8,Rates!$B$4:$D$100,3,FALSE),"") | E8: =IF(A8="","",IF(Inputs!$B$6="Erect Only",0,B8*D8))
D9: =IFERROR(VLOOKUP(A9,Rates!$B$4:$D$100,3,FALSE),"") | E9: =IF(A9="","",IF(Inputs!$B$6="Erect Only",0,B9*D9))
D10: =IFERROR(VLOOKUP(A10,Rates!$B$4:$D$100,3,FALSE),"") | E10: =IF(A10="","",IF(Inputs!$B$6="Erect Only",0,B10*D10))
D11: =IFERROR(VLOOKUP(A11,Rates!$B$4:$D$100,3,FALSE),"") | E11: =IF(A11="","",IF(Inputs!$B$6="Erect Only",0,B11*D11))
D12: =IFERROR(VLOOKUP(A12,Rates!$B$4:$D$100,3,FALSE),"") | E12: =IF(A12="","",IF(Inputs!$B$6="Erect Only",0,B12*D12))
D13: =IFERROR(VLOOKUP(A13,Rates!$B$4:$D$100,3,FALSE),"") | E13: =IF(A13="","",IF(Inputs!$B$6="Erect Only",0,B13*D13))
D14: =IFERROR(VLOOKUP(A14,Rates!$B$4:$D$100,3,FALSE),"") | E14: =IF(A14="","",IF(Inputs!$B$6="Erect Only",0,B14*D14))
D15: =IFERROR(VLOOKUP(A15,Rates!$B$4:$D$100,3,FALSE),"") | E15: =IF(A15="","",IF(Inputs!$B$6="Erect Only",0,B15*D15))
D16: =IFERROR(VLOOKUP(A16,Rates!$B$4:$D$100,3,FALSE),"") | E16: =IF(A16="","",IF(Inputs!$B$6="Erect Only",0,B16*D16))
... D20: =IFERROR(VLOOKUP(A20,Rates!$B$4:$D$100,3,FALSE),"") | E20: =IF(A20="","",IF(Inputs!$B$6="Erect Only",0,B20*D20))
A21: TOTAL | E21: =SUM(E2:E20)

Sheet Bid Summary
A1: Bid Summary
A3: Tonnage Material Subtotal | B3: ='Section 5 - Pricing'!J32
A4: Buyout & Hardware Subtotal | B4: ='Buyout & Hardware'!E21
A5: Joist & Deck Cost (input) | B5: 0
A6: Joist & Deck After Markup | B6: =IF(Inputs!$B$6="Erect Only",0,B5*(1+Inputs!$B$10))
A7: Taxable Base (material + hardware + J&D) | B7: =B3+B4+B6
A8: Erection Labor Subtotal | B8: ='Section 5 - Pricing'!K32
A9: Equipment Subtotal | B9: ='Section 5 - Pricing'!L32
A10: Freight (input) | B10: 1200
A11: Engineering (input) | B11: 0
A12: Detailing (input) | B12: 1663.6865
A13: Non-Taxable Subtotal | B13: =SUM(B8:B12)
A14: Direct Cost Subtotal (Sub Total) | B14: =B7+B13
A15: Bond Required? (Yes/No) | B15: No
A16: Bond Rate (%) - of Sub Total; leave blank if using flat $ below
A17: Bond Amount ($, flat) - leave blank if using Bond Rate % above
A18: Bond Total ($) | B18: =IF(B15<>"Yes",0,IF(B16="",IF(B17="",0,B17),B14*B16))
A19: Profit (Profit Floor % x Sub Total, excludes Bond) | B19: =B14*Inputs!$B$9
A20: Tax (Tax Rate x Taxable Base, $0 if exempt; excludes Bond) | B20: =IF(Inputs!$B$7="Yes",0,B7*Inputs!$B$8)
A21: Pre-Rounding Total (Sub Total + Bond + Profit + Tax) | B21: =B14+B18+B19+B20
A22: Grand Total (rounded up) | B22: =CEILING(B21,Inputs!$B$12)
A23: Margin Sanity Check (Profit / Grand Total) | B23: =B19/B22
A24: Sanity Check Result | B24: =IF(B23>=Inputs!$B$11,"PASS","BELOW TARGET - raise Profit Floor % in Inputs, do not change material rates or skip rounding")
